[I 200413 18:05:15 command:136] Visit me at http://localhost:5555
[I 200413 18:05:15 command:141] Broker: redis://192.168.180.133:6379/1
[I 200413 18:05:15 command:144] Registered tasks: 
    ['celery.backend_cleanup',
     'celery.chain',
     'celery.chord',
     'celery.chord_unlock',
     'celery.chunks',
     'celery.group',
     'celery.map',
     'celery.starmap',
     'dj_celery_demo']
[I 200413 18:05:15 mixins:231] Connected to redis://192.168.180.133:6379/1
/root/myenvs/my_dj_celery/lib/python3.6/site-packages/celery/app/control.py:36: DuplicateNodenameWarning: Received multiple replies from node name: celery@master-jenkins.
Please make sure you give each node a unique nodename using the `-n` option.
  pluralize(len(dupes), 'name'), ', '.join(sorted(dupes)),
[W 200413 18:05:44 control:44] 'stats' inspect method failed
[W 200413 18:05:44 control:44] 'registered' inspect method failed
[I 200413 20:34:16 command:136] Visit me at http://localhost:5555
[I 200413 20:34:16 command:141] Broker: redis://127.0.0.1:6379/1
[I 200413 20:34:16 command:144] Registered tasks: 
    ['celery.backend_cleanup',
     'celery.chain',
     'celery.chord',
     'celery.chord_unlock',
     'celery.chunks',
     'celery.group',
     'celery.map',
     'celery.starmap',
     'dj_celery_demo']
[I 200413 20:34:16 mixins:231] Connected to redis://127.0.0.1:6379/1
[W 200413 20:34:20 control:44] 'stats' inspect method failed
[W 200413 20:34:20 control:44] 'active_queues' inspect method failed
[W 200413 20:34:20 control:44] 'registered' inspect method failed
[W 200413 20:34:20 control:44] 'scheduled' inspect method failed
[W 200413 20:34:20 control:44] 'active' inspect method failed
[W 200413 20:34:20 control:44] 'reserved' inspect method failed
[W 200413 20:34:20 control:44] 'revoked' inspect method failed
[W 200413 20:34:20 control:44] 'conf' inspect method failed
[I 200413 22:18:31 command:136] Visit me at http://localhost:5555
[I 200413 22:18:31 command:141] Broker: redis://127.0.0.1:6379/1
[I 200413 22:18:31 command:144] Registered tasks: 
    ['celery.backend_cleanup',
     'celery.chain',
     'celery.chord',
     'celery.chord_unlock',
     'celery.chunks',
     'celery.group',
     'celery.map',
     'celery.starmap',
     'dj_celery_demo']
[I 200413 22:18:31 mixins:231] Connected to redis://127.0.0.1:6379/1
[W 200413 22:18:34 control:44] 'stats' inspect method failed
[W 200413 22:18:34 control:44] 'active_queues' inspect method failed
[W 200413 22:18:34 control:44] 'registered' inspect method failed
[W 200413 22:18:34 control:44] 'scheduled' inspect method failed
[W 200413 22:18:34 control:44] 'active' inspect method failed
[W 200413 22:18:34 control:44] 'reserved' inspect method failed
[W 200413 22:18:34 control:44] 'revoked' inspect method failed
[W 200413 22:18:34 control:44] 'conf' inspect method failed
[I 200414 10:32:02 command:136] Visit me at http://localhost:5555
[I 200414 10:32:02 command:141] Broker: redis://127.0.0.1:6379/1
[I 200414 10:32:02 command:144] Registered tasks: 
    ['celery.backend_cleanup',
     'celery.chain',
     'celery.chord',
     'celery.chord_unlock',
     'celery.chunks',
     'celery.group',
     'celery.map',
     'celery.starmap',
     'dj_celery_demo']
[I 200414 10:32:02 mixins:231] Connected to redis://127.0.0.1:6379/1
[W 200414 10:32:05 control:44] 'stats' inspect method failed
[W 200414 10:32:05 control:44] 'active_queues' inspect method failed
[W 200414 10:32:05 control:44] 'registered' inspect method failed
[W 200414 10:32:05 control:44] 'scheduled' inspect method failed
[W 200414 10:32:05 control:44] 'active' inspect method failed
[W 200414 10:32:05 control:44] 'reserved' inspect method failed
[W 200414 10:32:05 control:44] 'revoked' inspect method failed
[W 200414 10:32:05 control:44] 'conf' inspect method failed
[I 200414 10:40:32 command:44] SIGTERM detected, shutting down
[I 200414 10:41:04 command:136] Visit me at http://localhost:5555
[I 200414 10:41:04 command:141] Broker: redis://127.0.0.1:6379/1
[I 200414 10:41:04 command:144] Registered tasks: 
    ['celery.backend_cleanup',
     'celery.chain',
     'celery.chord',
     'celery.chord_unlock',
     'celery.chunks',
     'celery.group',
     'celery.map',
     'celery.starmap',
     'dj_celery_demo']
[I 200414 10:41:04 mixins:231] Connected to redis://127.0.0.1:6379/1
[W 200414 10:41:08 control:44] 'stats' inspect method failed
[W 200414 10:41:08 control:44] 'active_queues' inspect method failed
[W 200414 10:41:08 control:44] 'registered' inspect method failed
[W 200414 10:41:08 control:44] 'scheduled' inspect method failed
[W 200414 10:41:08 control:44] 'active' inspect method failed
[W 200414 10:41:08 control:44] 'reserved' inspect method failed
[W 200414 10:41:08 control:44] 'revoked' inspect method failed
[W 200414 10:41:08 control:44] 'conf' inspect method failed
[I 200414 10:41:45 command:44] SIGTERM detected, shutting down
[I 200414 11:07:28 command:136] Visit me at http://localhost:5555
[I 200414 11:07:28 command:141] Broker: redis://127.0.0.1:6379/1
[I 200414 11:07:28 command:144] Registered tasks: 
    ['celery.backend_cleanup',
     'celery.chain',
     'celery.chord',
     'celery.chord_unlock',
     'celery.chunks',
     'celery.group',
     'celery.map',
     'celery.starmap',
     'dj_celery_demo']
[I 200414 11:07:28 mixins:231] Connected to redis://127.0.0.1:6379/1
[W 200414 11:07:32 control:44] 'stats' inspect method failed
[W 200414 11:07:32 control:44] 'active_queues' inspect method failed
[W 200414 11:07:32 control:44] 'registered' inspect method failed
[W 200414 11:07:32 control:44] 'scheduled' inspect method failed
[W 200414 11:07:32 control:44] 'active' inspect method failed
[W 200414 11:07:32 control:44] 'reserved' inspect method failed
[W 200414 11:07:32 control:44] 'revoked' inspect method failed
[W 200414 11:07:32 control:44] 'conf' inspect method failed
[I 200414 14:04:39 command:44] SIGTERM detected, shutting down
[I 200415 09:44:27 command:136] Visit me at http://localhost:5555
[I 200415 09:44:27 command:141] Broker: redis://127.0.0.1:6379/1
[I 200415 09:44:27 command:144] Registered tasks: 
    ['celery.backend_cleanup',
     'celery.chain',
     'celery.chord',
     'celery.chord_unlock',
     'celery.chunks',
     'celery.group',
     'celery.map',
     'celery.starmap',
     'dj_celery_demo']
[E 200415 09:44:28 events:125] Failed to capture events: '', trying again in 2 seconds.
[E 200415 09:44:29 gen:506] Multiple exceptions in yield list
    Traceback (most recent call last):
      File "/home/wx/pyenvs/dj_celery/lib/python3.6/site-packages/kombu/transport/virtual/__init__.py", line 789, in create_channel
        return self._avail_channels.pop()
    IndexError: pop from empty list
    
    During handling of the above exception, another exception occurred:
    
    Traceback (most recent call last):
      File "/home/wx/pyenvs/dj_celery/lib/python3.6/site-packages/redis/connection.py", line 484, in connect
        sock = self._connect()
      File "/home/wx/pyenvs/dj_celery/lib/python3.6/site-packages/redis/connection.py", line 541, in _connect
        raise err
      File "/home/wx/pyenvs/dj_celery/lib/python3.6/site-packages/redis/connection.py", line 529, in _connect
        sock.connect(socket_address)
    ConnectionRefusedError: [Errno 111] Connection refused
    
    During handling of the above exception, another exception occurred:
    
    Traceback (most recent call last):
      File "/home/wx/pyenvs/dj_celery/lib/python3.6/site-packages/redis/client.py", line 667, in execute_command
        connection.send_command(*args)
      File "/home/wx/pyenvs/dj_celery/lib/python3.6/site-packages/redis/connection.py", line 610, in send_command
        self.send_packed_command(self.pack_command(*args))
      File "/home/wx/pyenvs/dj_celery/lib/python3.6/site-packages/redis/connection.py", line 585, in send_packed_command
        self.connect()
      File "/home/wx/pyenvs/dj_celery/lib/python3.6/site-packages/redis/connection.py", line 489, in connect
        raise ConnectionError(self._error_message(e))
    redis.exceptions.ConnectionError: Error 111 connecting to 127.0.0.1:6379. Connection refused.
    
    During handling of the above exception, another exception occurred:
    
    Traceback (most recent call last):
      File "/home/wx/pyenvs/dj_celery/lib/python3.6/site-packages/kombu/transport/redis.py", line 464, in __init__
        self.client.info()
      File "/home/wx/pyenvs/dj_celery/lib/python3.6/site-packages/redis/client.py", line 760, in info
        return self.execute_command('INFO')
      File "/home/wx/pyenvs/dj_celery/lib/python3.6/site-packages/redis/client.py", line 670, in execute_command
        connection.disconnect()
      File "/home/wx/pyenvs/dj_celery/lib/python3.6/site-packages/kombu/transport/redis.py", line 866, in disconnect
        channel._on_connection_disconnect(self)
      File "/home/wx/pyenvs/dj_celery/lib/python3.6/site-packages/kombu/transport/redis.py", line 496, in _on_connection_disconnect
        self._disconnect_pools()
      File "/home/wx/pyenvs/dj_celery/lib/python3.6/site-packages/kombu/transport/redis.py", line 484, in _disconnect_pools
        self._async_pool.disconnect()
      File "/home/wx/pyenvs/dj_celery/lib/python3.6/site-packages/redis/connection.py", line 998, in disconnect
        connection.disconnect()
      File "/home/wx/pyenvs/dj_celery/lib/python3.6/site-packages/kombu/transport/redis.py", line 866, in disconnect
        channel._on_connection_disconnect(self)
      File "/home/wx/pyenvs/dj_celery/lib/python3.6/site-packages/kombu/transport/redis.py", line 498, in _on_connection_disconnect
        raise get_redis_ConnectionError()
    redis.exceptions.ConnectionError
    
    During handling of the above exception, another exception occurred:
    
    Traceback (most recent call last):
      File "/usr/lib/python3.6/concurrent/futures/thread.py", line 56, in run
        result = self.fn(*self.args, **self.kwargs)
      File "/home/wx/pyenvs/dj_celery/lib/python3.6/site-packages/celery/app/control.py", line 109, in conf
        return self._request('dump_conf', with_defaults=with_defaults)
      File "/home/wx/pyenvs/dj_celery/lib/python3.6/site-packages/celery/app/control.py", line 71, in _request
        timeout=self.timeout, reply=True,
      File "/home/wx/pyenvs/dj_celery/lib/python3.6/site-packages/celery/app/control.py", line 316, in broadcast
        limit, callback, channel=channel,
      File "/home/wx/pyenvs/dj_celery/lib/python3.6/site-packages/kombu/pidbox.py", line 283, in _broadcast
        chan = channel or self.connection.default_channel
      File "/home/wx/pyenvs/dj_celery/lib/python3.6/site-packages/kombu/connection.py", line 771, in default_channel
        self.connection
      File "/home/wx/pyenvs/dj_celery/lib/python3.6/site-packages/kombu/connection.py", line 756, in connection
        self._connection = self._establish_connection()
      File "/home/wx/pyenvs/dj_celery/lib/python3.6/site-packages/kombu/connection.py", line 711, in _establish_connection
        conn = self.transport.establish_connection()
      File "/home/wx/pyenvs/dj_celery/lib/python3.6/site-packages/kombu/transport/virtual/__init__.py", line 809, in establish_connection
        self._avail_channels.append(self.create_channel(self))
      File "/home/wx/pyenvs/dj_celery/lib/python3.6/site-packages/kombu/transport/virtual/__init__.py", line 791, in create_channel
        channel = self.Channel(connection)
      File "/home/wx/pyenvs/dj_celery/lib/python3.6/site-packages/kombu/transport/redis.py", line 466, in __init__
        self._disconnect_pools()
      File "/home/wx/pyenvs/dj_celery/lib/python3.6/site-packages/kombu/transport/redis.py", line 484, in _disconnect_pools
        self._async_pool.disconnect()
      File "/home/wx/pyenvs/dj_celery/lib/python3.6/site-packages/redis/connection.py", line 998, in disconnect
        connection.disconnect()
      File "/home/wx/pyenvs/dj_celery/lib/python3.6/site-packages/kombu/transport/redis.py", line 866, in disconnect
        channel._on_connection_disconnect(self)
      File "/home/wx/pyenvs/dj_celery/lib/python3.6/site-packages/kombu/transport/redis.py", line 498, in _on_connection_disconnect
        raise get_redis_ConnectionError()
    redis.exceptions.ConnectionError
    
    During handling of the above exception, another exception occurred:
    
    Traceback (most recent call last):
      File "/home/wx/pyenvs/dj_celery/lib/python3.6/site-packages/tornado/gen.py", line 501, in callback
        result_list.append(f.result())
      File "/usr/lib/python3.6/concurrent/futures/_base.py", line 425, in result
        return self.__get_result()
      File "/usr/lib/python3.6/concurrent/futures/_base.py", line 384, in __get_result
        raise self._exception
      File "/usr/lib/python3.6/concurrent/futures/thread.py", line 56, in run
        result = self.fn(*self.args, **self.kwargs)
      File "/home/wx/pyenvs/dj_celery/lib/python3.6/site-packages/celery/app/control.py", line 103, in active_queues
        return self._request('active_queues')
      File "/home/wx/pyenvs/dj_celery/lib/python3.6/site-packages/celery/app/control.py", line 71, in _request
        timeout=self.timeout, reply=True,
      File "/home/wx/pyenvs/dj_celery/lib/python3.6/site-packages/celery/app/control.py", line 316, in broadcast
        limit, callback, channel=channel,
      File "/home/wx/pyenvs/dj_celery/lib/python3.6/site-packages/kombu/pidbox.py", line 283, in _broadcast
        chan = channel or self.connection.default_channel
      File "/home/wx/pyenvs/dj_celery/lib/python3.6/site-packages/kombu/connection.py", line 771, in default_channel
        self.connection
      File "/home/wx/pyenvs/dj_celery/lib/python3.6/site-packages/kombu/connection.py", line 756, in connection
        self._connection = self._establish_connection()
      File "/home/wx/pyenvs/dj_celery/lib/python3.6/site-packages/kombu/connection.py", line 711, in _establish_connection
        conn = self.transport.establish_connection()
      File "/home/wx/pyenvs/dj_celery/lib/python3.6/site-packages/kombu/transport/virtual/__init__.py", line 809, in establish_connection
        self._avail_channels.append(self.create_channel(self))
      File "/home/wx/pyenvs/dj_celery/lib/python3.6/site-packages/kombu/transport/virtual/__init__.py", line 791, in create_channel
        channel = self.Channel(connection)
      File "/home/wx/pyenvs/dj_celery/lib/python3.6/site-packages/kombu/transport/redis.py", line 466, in __init__
        self._disconnect_pools()
      File "/home/wx/pyenvs/dj_celery/lib/python3.6/site-packages/kombu/transport/redis.py", line 484, in _disconnect_pools
        self._async_pool.disconnect()
      File "/home/wx/pyenvs/dj_celery/lib/python3.6/site-packages/redis/connection.py", line 998, in disconnect
        connection.disconnect()
      File "/home/wx/pyenvs/dj_celery/lib/python3.6/site-packages/kombu/transport/redis.py", line 866, in disconnect
        channel._on_connection_disconnect(self)
      File "/home/wx/pyenvs/dj_celery/lib/python3.6/site-packages/kombu/transport/redis.py", line 498, in _on_connection_disconnect
        raise get_redis_ConnectionError()
    redis.exceptions.ConnectionError
[E 200415 09:44:29 gen:506] Multiple exceptions in yield list
    Traceback (most recent call last):
      File "/home/wx/pyenvs/dj_celery/lib/python3.6/site-packages/kombu/transport/virtual/__init__.py", line 789, in create_channel
        return self._avail_channels.pop()
    IndexError: pop from empty list
    
    During handling of the above exception, another exception occurred:
    
    Traceback (most recent call last):
      File "/home/wx/pyenvs/dj_celery/lib/python3.6/site-packages/redis/connection.py", line 484, in connect
        sock = self._connect()
      File "/home/wx/pyenvs/dj_celery/lib/python3.6/site-packages/redis/connection.py", line 541, in _connect
        raise err
      File "/home/wx/pyenvs/dj_celery/lib/python3.6/site-packages/redis/connection.py", line 529, in _connect
        sock.connect(socket_address)
    ConnectionRefusedError: [Errno 111] Connection refused
    
    During handling of the above exception, another exception occurred:
    
    Traceback (most recent call last):
      File "/home/wx/pyenvs/dj_celery/lib/python3.6/site-packages/redis/client.py", line 667, in execute_command
        connection.send_command(*args)
      File "/home/wx/pyenvs/dj_celery/lib/python3.6/site-packages/redis/connection.py", line 610, in send_command
        self.send_packed_command(self.pack_command(*args))
      File "/home/wx/pyenvs/dj_celery/lib/python3.6/site-packages/redis/connection.py", line 585, in send_packed_command
        self.connect()
      File "/home/wx/pyenvs/dj_celery/lib/python3.6/site-packages/redis/connection.py", line 489, in connect
        raise ConnectionError(self._error_message(e))
    redis.exceptions.ConnectionError: Error 111 connecting to 127.0.0.1:6379. Connection refused.
    
    During handling of the above exception, another exception occurred:
    
    Traceback (most recent call last):
      File "/home/wx/pyenvs/dj_celery/lib/python3.6/site-packages/kombu/transport/redis.py", line 464, in __init__
        self.client.info()
      File "/home/wx/pyenvs/dj_celery/lib/python3.6/site-packages/redis/client.py", line 760, in info
        return self.execute_command('INFO')
      File "/home/wx/pyenvs/dj_celery/lib/python3.6/site-packages/redis/client.py", line 670, in execute_command
        connection.disconnect()
      File "/home/wx/pyenvs/dj_celery/lib/python3.6/site-packages/kombu/transport/redis.py", line 866, in disconnect
        channel._on_connection_disconnect(self)
      File "/home/wx/pyenvs/dj_celery/lib/python3.6/site-packages/kombu/transport/redis.py", line 496, in _on_connection_disconnect
        self._disconnect_pools()
      File "/home/wx/pyenvs/dj_celery/lib/python3.6/site-packages/kombu/transport/redis.py", line 484, in _disconnect_pools
        self._async_pool.disconnect()
      File "/home/wx/pyenvs/dj_celery/lib/python3.6/site-packages/redis/connection.py", line 998, in disconnect
        connection.disconnect()
      File "/home/wx/pyenvs/dj_celery/lib/python3.6/site-packages/kombu/transport/redis.py", line 866, in disconnect
        channel._on_connection_disconnect(self)
      File "/home/wx/pyenvs/dj_celery/lib/python3.6/site-packages/kombu/transport/redis.py", line 498, in _on_connection_disconnect
        raise get_redis_ConnectionError()
    redis.exceptions.ConnectionError
    
    During handling of the above exception, another exception occurred:
    
    Traceback (most recent call last):
      File "/usr/lib/python3.6/concurrent/futures/thread.py", line 56, in run
        result = self.fn(*self.args, **self.kwargs)
      File "/home/wx/pyenvs/dj_celery/lib/python3.6/site-packages/celery/app/control.py", line 109, in conf
        return self._request('dump_conf', with_defaults=with_defaults)
      File "/home/wx/pyenvs/dj_celery/lib/python3.6/site-packages/celery/app/control.py", line 71, in _request
        timeout=self.timeout, reply=True,
      File "/home/wx/pyenvs/dj_celery/lib/python3.6/site-packages/celery/app/control.py", line 316, in broadcast
        limit, callback, channel=channel,
      File "/home/wx/pyenvs/dj_celery/lib/python3.6/site-packages/kombu/pidbox.py", line 283, in _broadcast
        chan = channel or self.connection.default_channel
      File "/home/wx/pyenvs/dj_celery/lib/python3.6/site-packages/kombu/connection.py", line 771, in default_channel
        self.connection
      File "/home/wx/pyenvs/dj_celery/lib/python3.6/site-packages/kombu/connection.py", line 756, in connection
        self._connection = self._establish_connection()
      File "/home/wx/pyenvs/dj_celery/lib/python3.6/site-packages/kombu/connection.py", line 711, in _establish_connection
        conn = self.transport.establish_connection()
      File "/home/wx/pyenvs/dj_celery/lib/python3.6/site-packages/kombu/transport/virtual/__init__.py", line 809, in establish_connection
        self._avail_channels.append(self.create_channel(self))
      File "/home/wx/pyenvs/dj_celery/lib/python3.6/site-packages/kombu/transport/virtual/__init__.py", line 791, in create_channel
        channel = self.Channel(connection)
      File "/home/wx/pyenvs/dj_celery/lib/python3.6/site-packages/kombu/transport/redis.py", line 466, in __init__
        self._disconnect_pools()
      File "/home/wx/pyenvs/dj_celery/lib/python3.6/site-packages/kombu/transport/redis.py", line 484, in _disconnect_pools
        self._async_pool.disconnect()
      File "/home/wx/pyenvs/dj_celery/lib/python3.6/site-packages/redis/connection.py", line 998, in disconnect
        connection.disconnect()
      File "/home/wx/pyenvs/dj_celery/lib/python3.6/site-packages/kombu/transport/redis.py", line 866, in disconnect
        channel._on_connection_disconnect(self)
      File "/home/wx/pyenvs/dj_celery/lib/python3.6/site-packages/kombu/transport/redis.py", line 498, in _on_connection_disconnect
        raise get_redis_ConnectionError()
    redis.exceptions.ConnectionError
    
    During handling of the above exception, another exception occurred:
    
    Traceback (most recent call last):
      File "/home/wx/pyenvs/dj_celery/lib/python3.6/site-packages/tornado/gen.py", line 501, in callback
        result_list.append(f.result())
      File "/usr/lib/python3.6/concurrent/futures/_base.py", line 425, in result
        return self.__get_result()
      File "/usr/lib/python3.6/concurrent/futures/_base.py", line 384, in __get_result
        raise self._exception
      File "/usr/lib/python3.6/concurrent/futures/thread.py", line 56, in run
        result = self.fn(*self.args, **self.kwargs)
      File "/home/wx/pyenvs/dj_celery/lib/python3.6/site-packages/celery/app/control.py", line 96, in registered
        return self._request('dump_tasks', taskinfoitems=taskinfoitems)
      File "/home/wx/pyenvs/dj_celery/lib/python3.6/site-packages/celery/app/control.py", line 71, in _request
        timeout=self.timeout, reply=True,
      File "/home/wx/pyenvs/dj_celery/lib/python3.6/site-packages/celery/app/control.py", line 316, in broadcast
        limit, callback, channel=channel,
      File "/home/wx/pyenvs/dj_celery/lib/python3.6/site-packages/kombu/pidbox.py", line 283, in _broadcast
        chan = channel or self.connection.default_channel
      File "/home/wx/pyenvs/dj_celery/lib/python3.6/site-packages/kombu/connection.py", line 771, in default_channel
        self.connection
      File "/home/wx/pyenvs/dj_celery/lib/python3.6/site-packages/kombu/connection.py", line 756, in connection
        self._connection = self._establish_connection()
      File "/home/wx/pyenvs/dj_celery/lib/python3.6/site-packages/kombu/connection.py", line 711, in _establish_connection
        conn = self.transport.establish_connection()
      File "/home/wx/pyenvs/dj_celery/lib/python3.6/site-packages/kombu/transport/virtual/__init__.py", line 809, in establish_connection
        self._avail_channels.append(self.create_channel(self))
      File "/home/wx/pyenvs/dj_celery/lib/python3.6/site-packages/kombu/transport/virtual/__init__.py", line 791, in create_channel
        channel = self.Channel(connection)
      File "/home/wx/pyenvs/dj_celery/lib/python3.6/site-packages/kombu/transport/redis.py", line 466, in __init__
        self._disconnect_pools()
      File "/home/wx/pyenvs/dj_celery/lib/python3.6/site-packages/kombu/transport/redis.py", line 484, in _disconnect_pools
        self._async_pool.disconnect()
      File "/home/wx/pyenvs/dj_celery/lib/python3.6/site-packages/redis/connection.py", line 998, in disconnect
        connection.disconnect()
      File "/home/wx/pyenvs/dj_celery/lib/python3.6/site-packages/kombu/transport/redis.py", line 866, in disconnect
        channel._on_connection_disconnect(self)
      File "/home/wx/pyenvs/dj_celery/lib/python3.6/site-packages/kombu/transport/redis.py", line 498, in _on_connection_disconnect
        raise get_redis_ConnectionError()
    redis.exceptions.ConnectionError
[E 200415 09:44:29 gen:506] Multiple exceptions in yield list
    Traceback (most recent call last):
      File "/home/wx/pyenvs/dj_celery/lib/python3.6/site-packages/kombu/transport/virtual/__init__.py", line 789, in create_channel
        return self._avail_channels.pop()
    IndexError: pop from empty list
    
    During handling of the above exception, another exception occurred:
    
    Traceback (most recent call last):
      File "/home/wx/pyenvs/dj_celery/lib/python3.6/site-packages/redis/connection.py", line 484, in connect
        sock = self._connect()
      File "/home/wx/pyenvs/dj_celery/lib/python3.6/site-packages/redis/connection.py", line 541, in _connect
        raise err
      File "/home/wx/pyenvs/dj_celery/lib/python3.6/site-packages/redis/connection.py", line 529, in _connect
        sock.connect(socket_address)
    ConnectionRefusedError: [Errno 111] Connection refused
    
    During handling of the above exception, another exception occurred:
    
    Traceback (most recent call last):
      File "/home/wx/pyenvs/dj_celery/lib/python3.6/site-packages/redis/client.py", line 667, in execute_command
        connection.send_command(*args)
      File "/home/wx/pyenvs/dj_celery/lib/python3.6/site-packages/redis/connection.py", line 610, in send_command
        self.send_packed_command(self.pack_command(*args))
      File "/home/wx/pyenvs/dj_celery/lib/python3.6/site-packages/redis/connection.py", line 585, in send_packed_command
        self.connect()
      File "/home/wx/pyenvs/dj_celery/lib/python3.6/site-packages/redis/connection.py", line 489, in connect
        raise ConnectionError(self._error_message(e))
    redis.exceptions.ConnectionError: Error 111 connecting to 127.0.0.1:6379. Connection refused.
    
    During handling of the above exception, another exception occurred:
    
    Traceback (most recent call last):
      File "/home/wx/pyenvs/dj_celery/lib/python3.6/site-packages/kombu/transport/redis.py", line 464, in __init__
        self.client.info()
      File "/home/wx/pyenvs/dj_celery/lib/python3.6/site-packages/redis/client.py", line 760, in info
        return self.execute_command('INFO')
      File "/home/wx/pyenvs/dj_celery/lib/python3.6/site-packages/redis/client.py", line 670, in execute_command
        connection.disconnect()
      File "/home/wx/pyenvs/dj_celery/lib/python3.6/site-packages/kombu/transport/redis.py", line 866, in disconnect
        channel._on_connection_disconnect(self)
      File "/home/wx/pyenvs/dj_celery/lib/python3.6/site-packages/kombu/transport/redis.py", line 496, in _on_connection_disconnect
        self._disconnect_pools()
      File "/home/wx/pyenvs/dj_celery/lib/python3.6/site-packages/kombu/transport/redis.py", line 484, in _disconnect_pools
        self._async_pool.disconnect()
      File "/home/wx/pyenvs/dj_celery/lib/python3.6/site-packages/redis/connection.py", line 998, in disconnect
        connection.disconnect()
      File "/home/wx/pyenvs/dj_celery/lib/python3.6/site-packages/kombu/transport/redis.py", line 866, in disconnect
        channel._on_connection_disconnect(self)
      File "/home/wx/pyenvs/dj_celery/lib/python3.6/site-packages/kombu/transport/redis.py", line 498, in _on_connection_disconnect
        raise get_redis_ConnectionError()
    redis.exceptions.ConnectionError
    
    During handling of the above exception, another exception occurred:
    
    Traceback (most recent call last):
      File "/usr/lib/python3.6/concurrent/futures/thread.py", line 56, in run
        result = self.fn(*self.args, **self.kwargs)
      File "/home/wx/pyenvs/dj_celery/lib/python3.6/site-packages/celery/app/control.py", line 109, in conf
        return self._request('dump_conf', with_defaults=with_defaults)
      File "/home/wx/pyenvs/dj_celery/lib/python3.6/site-packages/celery/app/control.py", line 71, in _request
        timeout=self.timeout, reply=True,
      File "/home/wx/pyenvs/dj_celery/lib/python3.6/site-packages/celery/app/control.py", line 316, in broadcast
        limit, callback, channel=channel,
      File "/home/wx/pyenvs/dj_celery/lib/python3.6/site-packages/kombu/pidbox.py", line 283, in _broadcast
        chan = channel or self.connection.default_channel
      File "/home/wx/pyenvs/dj_celery/lib/python3.6/site-packages/kombu/connection.py", line 771, in default_channel
        self.connection
      File "/home/wx/pyenvs/dj_celery/lib/python3.6/site-packages/kombu/connection.py", line 756, in connection
        self._connection = self._establish_connection()
      File "/home/wx/pyenvs/dj_celery/lib/python3.6/site-packages/kombu/connection.py", line 711, in _establish_connection
        conn = self.transport.establish_connection()
      File "/home/wx/pyenvs/dj_celery/lib/python3.6/site-packages/kombu/transport/virtual/__init__.py", line 809, in establish_connection
        self._avail_channels.append(self.create_channel(self))
      File "/home/wx/pyenvs/dj_celery/lib/python3.6/site-packages/kombu/transport/virtual/__init__.py", line 791, in create_channel
        channel = self.Channel(connection)
      File "/home/wx/pyenvs/dj_celery/lib/python3.6/site-packages/kombu/transport/redis.py", line 466, in __init__
        self._disconnect_pools()
      File "/home/wx/pyenvs/dj_celery/lib/python3.6/site-packages/kombu/transport/redis.py", line 484, in _disconnect_pools
        self._async_pool.disconnect()
      File "/home/wx/pyenvs/dj_celery/lib/python3.6/site-packages/redis/connection.py", line 998, in disconnect
        connection.disconnect()
      File "/home/wx/pyenvs/dj_celery/lib/python3.6/site-packages/kombu/transport/redis.py", line 866, in disconnect
        channel._on_connection_disconnect(self)
      File "/home/wx/pyenvs/dj_celery/lib/python3.6/site-packages/kombu/transport/redis.py", line 498, in _on_connection_disconnect
        raise get_redis_ConnectionError()
    redis.exceptions.ConnectionError
    
    During handling of the above exception, another exception occurred:
    
    Traceback (most recent call last):
      File "/home/wx/pyenvs/dj_celery/lib/python3.6/site-packages/tornado/gen.py", line 501, in callback
        result_list.append(f.result())
      File "/usr/lib/python3.6/concurrent/futures/_base.py", line 425, in result
        return self.__get_result()
      File "/usr/lib/python3.6/concurrent/futures/_base.py", line 384, in __get_result
        raise self._exception
      File "/usr/lib/python3.6/concurrent/futures/thread.py", line 56, in run
        result = self.fn(*self.args, **self.kwargs)
      File "/home/wx/pyenvs/dj_celery/lib/python3.6/site-packages/celery/app/control.py", line 84, in scheduled
        return self._request('dump_schedule', safe=safe)
      File "/home/wx/pyenvs/dj_celery/lib/python3.6/site-packages/celery/app/control.py", line 71, in _request
        timeout=self.timeout, reply=True,
      File "/home/wx/pyenvs/dj_celery/lib/python3.6/site-packages/celery/app/control.py", line 316, in broadcast
        limit, callback, channel=channel,
      File "/home/wx/pyenvs/dj_celery/lib/python3.6/site-packages/kombu/pidbox.py", line 283, in _broadcast
        chan = channel or self.connection.default_channel
      File "/home/wx/pyenvs/dj_celery/lib/python3.6/site-packages/kombu/connection.py", line 771, in default_channel
        self.connection
      File "/home/wx/pyenvs/dj_celery/lib/python3.6/site-packages/kombu/connection.py", line 756, in connection
        self._connection = self._establish_connection()
      File "/home/wx/pyenvs/dj_celery/lib/python3.6/site-packages/kombu/connection.py", line 711, in _establish_connection
        conn = self.transport.establish_connection()
      File "/home/wx/pyenvs/dj_celery/lib/python3.6/site-packages/kombu/transport/virtual/__init__.py", line 809, in establish_connection
        self._avail_channels.append(self.create_channel(self))
      File "/home/wx/pyenvs/dj_celery/lib/python3.6/site-packages/kombu/transport/virtual/__init__.py", line 791, in create_channel
        channel = self.Channel(connection)
      File "/home/wx/pyenvs/dj_celery/lib/python3.6/site-packages/kombu/transport/redis.py", line 466, in __init__
        self._disconnect_pools()
      File "/home/wx/pyenvs/dj_celery/lib/python3.6/site-packages/kombu/transport/redis.py", line 484, in _disconnect_pools
        self._async_pool.disconnect()
      File "/home/wx/pyenvs/dj_celery/lib/python3.6/site-packages/redis/connection.py", line 998, in disconnect
        connection.disconnect()
      File "/home/wx/pyenvs/dj_celery/lib/python3.6/site-packages/kombu/transport/redis.py", line 866, in disconnect
        channel._on_connection_disconnect(self)
      File "/home/wx/pyenvs/dj_celery/lib/python3.6/site-packages/kombu/transport/redis.py", line 498, in _on_connection_disconnect
        raise get_redis_ConnectionError()
    redis.exceptions.ConnectionError
[E 200415 09:44:29 gen:506] Multiple exceptions in yield list
    Traceback (most recent call last):
      File "/home/wx/pyenvs/dj_celery/lib/python3.6/site-packages/kombu/transport/virtual/__init__.py", line 789, in create_channel
        return self._avail_channels.pop()
    IndexError: pop from empty list
    
    During handling of the above exception, another exception occurred:
    
    Traceback (most recent call last):
      File "/home/wx/pyenvs/dj_celery/lib/python3.6/site-packages/redis/connection.py", line 484, in connect
        sock = self._connect()
      File "/home/wx/pyenvs/dj_celery/lib/python3.6/site-packages/redis/connection.py", line 541, in _connect
        raise err
      File "/home/wx/pyenvs/dj_celery/lib/python3.6/site-packages/redis/connection.py", line 529, in _connect
        sock.connect(socket_address)
    ConnectionRefusedError: [Errno 111] Connection refused
    
    During handling of the above exception, another exception occurred:
    
    Traceback (most recent call last):
      File "/home/wx/pyenvs/dj_celery/lib/python3.6/site-packages/redis/client.py", line 667, in execute_command
        connection.send_command(*args)
      File "/home/wx/pyenvs/dj_celery/lib/python3.6/site-packages/redis/connection.py", line 610, in send_command
        self.send_packed_command(self.pack_command(*args))
      File "/home/wx/pyenvs/dj_celery/lib/python3.6/site-packages/redis/connection.py", line 585, in send_packed_command
        self.connect()
      File "/home/wx/pyenvs/dj_celery/lib/python3.6/site-packages/redis/connection.py", line 489, in connect
        raise ConnectionError(self._error_message(e))
    redis.exceptions.ConnectionError: Error 111 connecting to 127.0.0.1:6379. Connection refused.
    
    During handling of the above exception, another exception occurred:
    
    Traceback (most recent call last):
      File "/home/wx/pyenvs/dj_celery/lib/python3.6/site-packages/kombu/transport/redis.py", line 464, in __init__
        self.client.info()
      File "/home/wx/pyenvs/dj_celery/lib/python3.6/site-packages/redis/client.py", line 760, in info
        return self.execute_command('INFO')
      File "/home/wx/pyenvs/dj_celery/lib/python3.6/site-packages/redis/client.py", line 670, in execute_command
        connection.disconnect()
      File "/home/wx/pyenvs/dj_celery/lib/python3.6/site-packages/kombu/transport/redis.py", line 866, in disconnect
        channel._on_connection_disconnect(self)
      File "/home/wx/pyenvs/dj_celery/lib/python3.6/site-packages/kombu/transport/redis.py", line 496, in _on_connection_disconnect
        self._disconnect_pools()
      File "/home/wx/pyenvs/dj_celery/lib/python3.6/site-packages/kombu/transport/redis.py", line 484, in _disconnect_pools
        self._async_pool.disconnect()
      File "/home/wx/pyenvs/dj_celery/lib/python3.6/site-packages/redis/connection.py", line 998, in disconnect
        connection.disconnect()
      File "/home/wx/pyenvs/dj_celery/lib/python3.6/site-packages/kombu/transport/redis.py", line 866, in disconnect
        channel._on_connection_disconnect(self)
      File "/home/wx/pyenvs/dj_celery/lib/python3.6/site-packages/kombu/transport/redis.py", line 498, in _on_connection_disconnect
        raise get_redis_ConnectionError()
    redis.exceptions.ConnectionError
    
    During handling of the above exception, another exception occurred:
    
    Traceback (most recent call last):
      File "/usr/lib/python3.6/concurrent/futures/thread.py", line 56, in run
        result = self.fn(*self.args, **self.kwargs)
      File "/home/wx/pyenvs/dj_celery/lib/python3.6/site-packages/celery/app/control.py", line 109, in conf
        return self._request('dump_conf', with_defaults=with_defaults)
      File "/home/wx/pyenvs/dj_celery/lib/python3.6/site-packages/celery/app/control.py", line 71, in _request
        timeout=self.timeout, reply=True,
      File "/home/wx/pyenvs/dj_celery/lib/python3.6/site-packages/celery/app/control.py", line 316, in broadcast
        limit, callback, channel=channel,
      File "/home/wx/pyenvs/dj_celery/lib/python3.6/site-packages/kombu/pidbox.py", line 283, in _broadcast
        chan = channel or self.connection.default_channel
      File "/home/wx/pyenvs/dj_celery/lib/python3.6/site-packages/kombu/connection.py", line 771, in default_channel
        self.connection
      File "/home/wx/pyenvs/dj_celery/lib/python3.6/site-packages/kombu/connection.py", line 756, in connection
        self._connection = self._establish_connection()
      File "/home/wx/pyenvs/dj_celery/lib/python3.6/site-packages/kombu/connection.py", line 711, in _establish_connection
        conn = self.transport.establish_connection()
      File "/home/wx/pyenvs/dj_celery/lib/python3.6/site-packages/kombu/transport/virtual/__init__.py", line 809, in establish_connection
        self._avail_channels.append(self.create_channel(self))
      File "/home/wx/pyenvs/dj_celery/lib/python3.6/site-packages/kombu/transport/virtual/__init__.py", line 791, in create_channel
        channel = self.Channel(connection)
      File "/home/wx/pyenvs/dj_celery/lib/python3.6/site-packages/kombu/transport/redis.py", line 466, in __init__
        self._disconnect_pools()
      File "/home/wx/pyenvs/dj_celery/lib/python3.6/site-packages/kombu/transport/redis.py", line 484, in _disconnect_pools
        self._async_pool.disconnect()
      File "/home/wx/pyenvs/dj_celery/lib/python3.6/site-packages/redis/connection.py", line 998, in disconnect
        connection.disconnect()
      File "/home/wx/pyenvs/dj_celery/lib/python3.6/site-packages/kombu/transport/redis.py", line 866, in disconnect
        channel._on_connection_disconnect(self)
      File "/home/wx/pyenvs/dj_celery/lib/python3.6/site-packages/kombu/transport/redis.py", line 498, in _on_connection_disconnect
        raise get_redis_ConnectionError()
    redis.exceptions.ConnectionError
    
    During handling of the above exception, another exception occurred:
    
    Traceback (most recent call last):
      File "/home/wx/pyenvs/dj_celery/lib/python3.6/site-packages/tornado/gen.py", line 501, in callback
        result_list.append(f.result())
      File "/usr/lib/python3.6/concurrent/futures/_base.py", line 425, in result
        return self.__get_result()
      File "/usr/lib/python3.6/concurrent/futures/_base.py", line 384, in __get_result
        raise self._exception
      File "/usr/lib/python3.6/concurrent/futures/thread.py", line 56, in run
        result = self.fn(*self.args, **self.kwargs)
      File "/home/wx/pyenvs/dj_celery/lib/python3.6/site-packages/celery/app/control.py", line 81, in active
        return self._request('dump_active', safe=safe)
      File "/home/wx/pyenvs/dj_celery/lib/python3.6/site-packages/celery/app/control.py", line 71, in _request
        timeout=self.timeout, reply=True,
      File "/home/wx/pyenvs/dj_celery/lib/python3.6/site-packages/celery/app/control.py", line 316, in broadcast
        limit, callback, channel=channel,
      File "/home/wx/pyenvs/dj_celery/lib/python3.6/site-packages/kombu/pidbox.py", line 283, in _broadcast
        chan = channel or self.connection.default_channel
      File "/home/wx/pyenvs/dj_celery/lib/python3.6/site-packages/kombu/connection.py", line 771, in default_channel
        self.connection
      File "/home/wx/pyenvs/dj_celery/lib/python3.6/site-packages/kombu/connection.py", line 756, in connection
        self._connection = self._establish_connection()
      File "/home/wx/pyenvs/dj_celery/lib/python3.6/site-packages/kombu/connection.py", line 711, in _establish_connection
        conn = self.transport.establish_connection()
      File "/home/wx/pyenvs/dj_celery/lib/python3.6/site-packages/kombu/transport/virtual/__init__.py", line 809, in establish_connection
        self._avail_channels.append(self.create_channel(self))
      File "/home/wx/pyenvs/dj_celery/lib/python3.6/site-packages/kombu/transport/virtual/__init__.py", line 791, in create_channel
        channel = self.Channel(connection)
      File "/home/wx/pyenvs/dj_celery/lib/python3.6/site-packages/kombu/transport/redis.py", line 466, in __init__
        self._disconnect_pools()
      File "/home/wx/pyenvs/dj_celery/lib/python3.6/site-packages/kombu/transport/redis.py", line 484, in _disconnect_pools
        self._async_pool.disconnect()
      File "/home/wx/pyenvs/dj_celery/lib/python3.6/site-packages/redis/connection.py", line 998, in disconnect
        connection.disconnect()
      File "/home/wx/pyenvs/dj_celery/lib/python3.6/site-packages/kombu/transport/redis.py", line 866, in disconnect
        channel._on_connection_disconnect(self)
      File "/home/wx/pyenvs/dj_celery/lib/python3.6/site-packages/kombu/transport/redis.py", line 498, in _on_connection_disconnect
        raise get_redis_ConnectionError()
    redis.exceptions.ConnectionError
[E 200415 09:44:29 gen:506] Multiple exceptions in yield list
    Traceback (most recent call last):
      File "/home/wx/pyenvs/dj_celery/lib/python3.6/site-packages/kombu/transport/virtual/__init__.py", line 789, in create_channel
        return self._avail_channels.pop()
    IndexError: pop from empty list
    
    During handling of the above exception, another exception occurred:
    
    Traceback (most recent call last):
      File "/home/wx/pyenvs/dj_celery/lib/python3.6/site-packages/redis/connection.py", line 484, in connect
        sock = self._connect()
      File "/home/wx/pyenvs/dj_celery/lib/python3.6/site-packages/redis/connection.py", line 541, in _connect
        raise err
      File "/home/wx/pyenvs/dj_celery/lib/python3.6/site-packages/redis/connection.py", line 529, in _connect
        sock.connect(socket_address)
    ConnectionRefusedError: [Errno 111] Connection refused
    
    During handling of the above exception, another exception occurred:
    
    Traceback (most recent call last):
      File "/home/wx/pyenvs/dj_celery/lib/python3.6/site-packages/redis/client.py", line 667, in execute_command
        connection.send_command(*args)
      File "/home/wx/pyenvs/dj_celery/lib/python3.6/site-packages/redis/connection.py", line 610, in send_command
        self.send_packed_command(self.pack_command(*args))
      File "/home/wx/pyenvs/dj_celery/lib/python3.6/site-packages/redis/connection.py", line 585, in send_packed_command
        self.connect()
      File "/home/wx/pyenvs/dj_celery/lib/python3.6/site-packages/redis/connection.py", line 489, in connect
        raise ConnectionError(self._error_message(e))
    redis.exceptions.ConnectionError: Error 111 connecting to 127.0.0.1:6379. Connection refused.
    
    During handling of the above exception, another exception occurred:
    
    Traceback (most recent call last):
      File "/home/wx/pyenvs/dj_celery/lib/python3.6/site-packages/kombu/transport/redis.py", line 464, in __init__
        self.client.info()
      File "/home/wx/pyenvs/dj_celery/lib/python3.6/site-packages/redis/client.py", line 760, in info
        return self.execute_command('INFO')
      File "/home/wx/pyenvs/dj_celery/lib/python3.6/site-packages/redis/client.py", line 670, in execute_command
        connection.disconnect()
      File "/home/wx/pyenvs/dj_celery/lib/python3.6/site-packages/kombu/transport/redis.py", line 866, in disconnect
        channel._on_connection_disconnect(self)
      File "/home/wx/pyenvs/dj_celery/lib/python3.6/site-packages/kombu/transport/redis.py", line 496, in _on_connection_disconnect
        self._disconnect_pools()
      File "/home/wx/pyenvs/dj_celery/lib/python3.6/site-packages/kombu/transport/redis.py", line 484, in _disconnect_pools
        self._async_pool.disconnect()
      File "/home/wx/pyenvs/dj_celery/lib/python3.6/site-packages/redis/connection.py", line 998, in disconnect
        connection.disconnect()
      File "/home/wx/pyenvs/dj_celery/lib/python3.6/site-packages/kombu/transport/redis.py", line 866, in disconnect
        channel._on_connection_disconnect(self)
      File "/home/wx/pyenvs/dj_celery/lib/python3.6/site-packages/kombu/transport/redis.py", line 498, in _on_connection_disconnect
        raise get_redis_ConnectionError()
    redis.exceptions.ConnectionError
    
    During handling of the above exception, another exception occurred:
    
    Traceback (most recent call last):
      File "/usr/lib/python3.6/concurrent/futures/thread.py", line 56, in run
        result = self.fn(*self.args, **self.kwargs)
      File "/home/wx/pyenvs/dj_celery/lib/python3.6/site-packages/celery/app/control.py", line 109, in conf
        return self._request('dump_conf', with_defaults=with_defaults)
      File "/home/wx/pyenvs/dj_celery/lib/python3.6/site-packages/celery/app/control.py", line 71, in _request
        timeout=self.timeout, reply=True,
      File "/home/wx/pyenvs/dj_celery/lib/python3.6/site-packages/celery/app/control.py", line 316, in broadcast
        limit, callback, channel=channel,
      File "/home/wx/pyenvs/dj_celery/lib/python3.6/site-packages/kombu/pidbox.py", line 283, in _broadcast
        chan = channel or self.connection.default_channel
      File "/home/wx/pyenvs/dj_celery/lib/python3.6/site-packages/kombu/connection.py", line 771, in default_channel
        self.connection
      File "/home/wx/pyenvs/dj_celery/lib/python3.6/site-packages/kombu/connection.py", line 756, in connection
        self._connection = self._establish_connection()
      File "/home/wx/pyenvs/dj_celery/lib/python3.6/site-packages/kombu/connection.py", line 711, in _establish_connection
        conn = self.transport.establish_connection()
      File "/home/wx/pyenvs/dj_celery/lib/python3.6/site-packages/kombu/transport/virtual/__init__.py", line 809, in establish_connection
        self._avail_channels.append(self.create_channel(self))
      File "/home/wx/pyenvs/dj_celery/lib/python3.6/site-packages/kombu/transport/virtual/__init__.py", line 791, in create_channel
        channel = self.Channel(connection)
      File "/home/wx/pyenvs/dj_celery/lib/python3.6/site-packages/kombu/transport/redis.py", line 466, in __init__
        self._disconnect_pools()
      File "/home/wx/pyenvs/dj_celery/lib/python3.6/site-packages/kombu/transport/redis.py", line 484, in _disconnect_pools
        self._async_pool.disconnect()
      File "/home/wx/pyenvs/dj_celery/lib/python3.6/site-packages/redis/connection.py", line 998, in disconnect
        connection.disconnect()
      File "/home/wx/pyenvs/dj_celery/lib/python3.6/site-packages/kombu/transport/redis.py", line 866, in disconnect
        channel._on_connection_disconnect(self)
      File "/home/wx/pyenvs/dj_celery/lib/python3.6/site-packages/kombu/transport/redis.py", line 498, in _on_connection_disconnect
        raise get_redis_ConnectionError()
    redis.exceptions.ConnectionError
    
    During handling of the above exception, another exception occurred:
    
    Traceback (most recent call last):
      File "/home/wx/pyenvs/dj_celery/lib/python3.6/site-packages/tornado/gen.py", line 501, in callback
        result_list.append(f.result())
      File "/usr/lib/python3.6/concurrent/futures/_base.py", line 425, in result
        return self.__get_result()
      File "/usr/lib/python3.6/concurrent/futures/_base.py", line 384, in __get_result
        raise self._exception
      File "/usr/lib/python3.6/concurrent/futures/thread.py", line 56, in run
        result = self.fn(*self.args, **self.kwargs)
      File "/home/wx/pyenvs/dj_celery/lib/python3.6/site-packages/celery/app/control.py", line 87, in reserved
        return self._request('dump_reserved', safe=safe)
      File "/home/wx/pyenvs/dj_celery/lib/python3.6/site-packages/celery/app/control.py", line 71, in _request
        timeout=self.timeout, reply=True,
      File "/home/wx/pyenvs/dj_celery/lib/python3.6/site-packages/celery/app/control.py", line 316, in broadcast
        limit, callback, channel=channel,
      File "/home/wx/pyenvs/dj_celery/lib/python3.6/site-packages/kombu/pidbox.py", line 283, in _broadcast
        chan = channel or self.connection.default_channel
      File "/home/wx/pyenvs/dj_celery/lib/python3.6/site-packages/kombu/connection.py", line 771, in default_channel
        self.connection
      File "/home/wx/pyenvs/dj_celery/lib/python3.6/site-packages/kombu/connection.py", line 756, in connection
        self._connection = self._establish_connection()
      File "/home/wx/pyenvs/dj_celery/lib/python3.6/site-packages/kombu/connection.py", line 711, in _establish_connection
        conn = self.transport.establish_connection()
      File "/home/wx/pyenvs/dj_celery/lib/python3.6/site-packages/kombu/transport/virtual/__init__.py", line 809, in establish_connection
        self._avail_channels.append(self.create_channel(self))
      File "/home/wx/pyenvs/dj_celery/lib/python3.6/site-packages/kombu/transport/virtual/__init__.py", line 791, in create_channel
        channel = self.Channel(connection)
      File "/home/wx/pyenvs/dj_celery/lib/python3.6/site-packages/kombu/transport/redis.py", line 466, in __init__
        self._disconnect_pools()
      File "/home/wx/pyenvs/dj_celery/lib/python3.6/site-packages/kombu/transport/redis.py", line 484, in _disconnect_pools
        self._async_pool.disconnect()
      File "/home/wx/pyenvs/dj_celery/lib/python3.6/site-packages/redis/connection.py", line 998, in disconnect
        connection.disconnect()
      File "/home/wx/pyenvs/dj_celery/lib/python3.6/site-packages/kombu/transport/redis.py", line 866, in disconnect
        channel._on_connection_disconnect(self)
      File "/home/wx/pyenvs/dj_celery/lib/python3.6/site-packages/kombu/transport/redis.py", line 498, in _on_connection_disconnect
        raise get_redis_ConnectionError()
    redis.exceptions.ConnectionError
[E 200415 09:44:29 gen:506] Multiple exceptions in yield list
    Traceback (most recent call last):
      File "/home/wx/pyenvs/dj_celery/lib/python3.6/site-packages/kombu/transport/virtual/__init__.py", line 789, in create_channel
        return self._avail_channels.pop()
    IndexError: pop from empty list
    
    During handling of the above exception, another exception occurred:
    
    Traceback (most recent call last):
      File "/home/wx/pyenvs/dj_celery/lib/python3.6/site-packages/redis/connection.py", line 484, in connect
        sock = self._connect()
      File "/home/wx/pyenvs/dj_celery/lib/python3.6/site-packages/redis/connection.py", line 541, in _connect
        raise err
      File "/home/wx/pyenvs/dj_celery/lib/python3.6/site-packages/redis/connection.py", line 529, in _connect
        sock.connect(socket_address)
    ConnectionRefusedError: [Errno 111] Connection refused
    
    During handling of the above exception, another exception occurred:
    
    Traceback (most recent call last):
      File "/home/wx/pyenvs/dj_celery/lib/python3.6/site-packages/redis/client.py", line 667, in execute_command
        connection.send_command(*args)
      File "/home/wx/pyenvs/dj_celery/lib/python3.6/site-packages/redis/connection.py", line 610, in send_command
        self.send_packed_command(self.pack_command(*args))
      File "/home/wx/pyenvs/dj_celery/lib/python3.6/site-packages/redis/connection.py", line 585, in send_packed_command
        self.connect()
      File "/home/wx/pyenvs/dj_celery/lib/python3.6/site-packages/redis/connection.py", line 489, in connect
        raise ConnectionError(self._error_message(e))
    redis.exceptions.ConnectionError: Error 111 connecting to 127.0.0.1:6379. Connection refused.
    
    During handling of the above exception, another exception occurred:
    
    Traceback (most recent call last):
      File "/home/wx/pyenvs/dj_celery/lib/python3.6/site-packages/kombu/transport/redis.py", line 464, in __init__
        self.client.info()
      File "/home/wx/pyenvs/dj_celery/lib/python3.6/site-packages/redis/client.py", line 760, in info
        return self.execute_command('INFO')
      File "/home/wx/pyenvs/dj_celery/lib/python3.6/site-packages/redis/client.py", line 670, in execute_command
        connection.disconnect()
      File "/home/wx/pyenvs/dj_celery/lib/python3.6/site-packages/kombu/transport/redis.py", line 866, in disconnect
        channel._on_connection_disconnect(self)
      File "/home/wx/pyenvs/dj_celery/lib/python3.6/site-packages/kombu/transport/redis.py", line 496, in _on_connection_disconnect
        self._disconnect_pools()
      File "/home/wx/pyenvs/dj_celery/lib/python3.6/site-packages/kombu/transport/redis.py", line 484, in _disconnect_pools
        self._async_pool.disconnect()
      File "/home/wx/pyenvs/dj_celery/lib/python3.6/site-packages/redis/connection.py", line 998, in disconnect
        connection.disconnect()
      File "/home/wx/pyenvs/dj_celery/lib/python3.6/site-packages/kombu/transport/redis.py", line 866, in disconnect
        channel._on_connection_disconnect(self)
      File "/home/wx/pyenvs/dj_celery/lib/python3.6/site-packages/kombu/transport/redis.py", line 498, in _on_connection_disconnect
        raise get_redis_ConnectionError()
    redis.exceptions.ConnectionError
    
    During handling of the above exception, another exception occurred:
    
    Traceback (most recent call last):
      File "/usr/lib/python3.6/concurrent/futures/thread.py", line 56, in run
        result = self.fn(*self.args, **self.kwargs)
      File "/home/wx/pyenvs/dj_celery/lib/python3.6/site-packages/celery/app/control.py", line 109, in conf
        return self._request('dump_conf', with_defaults=with_defaults)
      File "/home/wx/pyenvs/dj_celery/lib/python3.6/site-packages/celery/app/control.py", line 71, in _request
        timeout=self.timeout, reply=True,
      File "/home/wx/pyenvs/dj_celery/lib/python3.6/site-packages/celery/app/control.py", line 316, in broadcast
        limit, callback, channel=channel,
      File "/home/wx/pyenvs/dj_celery/lib/python3.6/site-packages/kombu/pidbox.py", line 283, in _broadcast
        chan = channel or self.connection.default_channel
      File "/home/wx/pyenvs/dj_celery/lib/python3.6/site-packages/kombu/connection.py", line 771, in default_channel
        self.connection
      File "/home/wx/pyenvs/dj_celery/lib/python3.6/site-packages/kombu/connection.py", line 756, in connection
        self._connection = self._establish_connection()
      File "/home/wx/pyenvs/dj_celery/lib/python3.6/site-packages/kombu/connection.py", line 711, in _establish_connection
        conn = self.transport.establish_connection()
      File "/home/wx/pyenvs/dj_celery/lib/python3.6/site-packages/kombu/transport/virtual/__init__.py", line 809, in establish_connection
        self._avail_channels.append(self.create_channel(self))
      File "/home/wx/pyenvs/dj_celery/lib/python3.6/site-packages/kombu/transport/virtual/__init__.py", line 791, in create_channel
        channel = self.Channel(connection)
      File "/home/wx/pyenvs/dj_celery/lib/python3.6/site-packages/kombu/transport/redis.py", line 466, in __init__
        self._disconnect_pools()
      File "/home/wx/pyenvs/dj_celery/lib/python3.6/site-packages/kombu/transport/redis.py", line 484, in _disconnect_pools
        self._async_pool.disconnect()
      File "/home/wx/pyenvs/dj_celery/lib/python3.6/site-packages/redis/connection.py", line 998, in disconnect
        connection.disconnect()
      File "/home/wx/pyenvs/dj_celery/lib/python3.6/site-packages/kombu/transport/redis.py", line 866, in disconnect
        channel._on_connection_disconnect(self)
      File "/home/wx/pyenvs/dj_celery/lib/python3.6/site-packages/kombu/transport/redis.py", line 498, in _on_connection_disconnect
        raise get_redis_ConnectionError()
    redis.exceptions.ConnectionError
    
    During handling of the above exception, another exception occurred:
    
    Traceback (most recent call last):
      File "/home/wx/pyenvs/dj_celery/lib/python3.6/site-packages/tornado/gen.py", line 501, in callback
        result_list.append(f.result())
      File "/usr/lib/python3.6/concurrent/futures/_base.py", line 425, in result
        return self.__get_result()
      File "/usr/lib/python3.6/concurrent/futures/_base.py", line 384, in __get_result
        raise self._exception
      File "/usr/lib/python3.6/concurrent/futures/thread.py", line 56, in run
        result = self.fn(*self.args, **self.kwargs)
      File "/home/wx/pyenvs/dj_celery/lib/python3.6/site-packages/celery/app/control.py", line 93, in revoked
        return self._request('dump_revoked')
      File "/home/wx/pyenvs/dj_celery/lib/python3.6/site-packages/celery/app/control.py", line 71, in _request
        timeout=self.timeout, reply=True,
      File "/home/wx/pyenvs/dj_celery/lib/python3.6/site-packages/celery/app/control.py", line 316, in broadcast
        limit, callback, channel=channel,
      File "/home/wx/pyenvs/dj_celery/lib/python3.6/site-packages/kombu/pidbox.py", line 283, in _broadcast
        chan = channel or self.connection.default_channel
      File "/home/wx/pyenvs/dj_celery/lib/python3.6/site-packages/kombu/connection.py", line 771, in default_channel
        self.connection
      File "/home/wx/pyenvs/dj_celery/lib/python3.6/site-packages/kombu/connection.py", line 756, in connection
        self._connection = self._establish_connection()
      File "/home/wx/pyenvs/dj_celery/lib/python3.6/site-packages/kombu/connection.py", line 711, in _establish_connection
        conn = self.transport.establish_connection()
      File "/home/wx/pyenvs/dj_celery/lib/python3.6/site-packages/kombu/transport/virtual/__init__.py", line 809, in establish_connection
        self._avail_channels.append(self.create_channel(self))
      File "/home/wx/pyenvs/dj_celery/lib/python3.6/site-packages/kombu/transport/virtual/__init__.py", line 791, in create_channel
        channel = self.Channel(connection)
      File "/home/wx/pyenvs/dj_celery/lib/python3.6/site-packages/kombu/transport/redis.py", line 466, in __init__
        self._disconnect_pools()
      File "/home/wx/pyenvs/dj_celery/lib/python3.6/site-packages/kombu/transport/redis.py", line 484, in _disconnect_pools
        self._async_pool.disconnect()
      File "/home/wx/pyenvs/dj_celery/lib/python3.6/site-packages/redis/connection.py", line 998, in disconnect
        connection.disconnect()
      File "/home/wx/pyenvs/dj_celery/lib/python3.6/site-packages/kombu/transport/redis.py", line 866, in disconnect
        channel._on_connection_disconnect(self)
      File "/home/wx/pyenvs/dj_celery/lib/python3.6/site-packages/kombu/transport/redis.py", line 498, in _on_connection_disconnect
        raise get_redis_ConnectionError()
    redis.exceptions.ConnectionError
[E 200415 09:44:29 gen:506] Multiple exceptions in yield list
    Traceback (most recent call last):
      File "/home/wx/pyenvs/dj_celery/lib/python3.6/site-packages/kombu/transport/virtual/__init__.py", line 789, in create_channel
        return self._avail_channels.pop()
    IndexError: pop from empty list
    
    During handling of the above exception, another exception occurred:
    
    Traceback (most recent call last):
      File "/home/wx/pyenvs/dj_celery/lib/python3.6/site-packages/redis/connection.py", line 484, in connect
        sock = self._connect()
      File "/home/wx/pyenvs/dj_celery/lib/python3.6/site-packages/redis/connection.py", line 541, in _connect
        raise err
      File "/home/wx/pyenvs/dj_celery/lib/python3.6/site-packages/redis/connection.py", line 529, in _connect
        sock.connect(socket_address)
    ConnectionRefusedError: [Errno 111] Connection refused
    
    During handling of the above exception, another exception occurred:
    
    Traceback (most recent call last):
      File "/home/wx/pyenvs/dj_celery/lib/python3.6/site-packages/redis/client.py", line 667, in execute_command
        connection.send_command(*args)
      File "/home/wx/pyenvs/dj_celery/lib/python3.6/site-packages/redis/connection.py", line 610, in send_command
        self.send_packed_command(self.pack_command(*args))
      File "/home/wx/pyenvs/dj_celery/lib/python3.6/site-packages/redis/connection.py", line 585, in send_packed_command
        self.connect()
      File "/home/wx/pyenvs/dj_celery/lib/python3.6/site-packages/redis/connection.py", line 489, in connect
        raise ConnectionError(self._error_message(e))
    redis.exceptions.ConnectionError: Error 111 connecting to 127.0.0.1:6379. Connection refused.
    
    During handling of the above exception, another exception occurred:
    
    Traceback (most recent call last):
      File "/home/wx/pyenvs/dj_celery/lib/python3.6/site-packages/kombu/transport/redis.py", line 464, in __init__
        self.client.info()
      File "/home/wx/pyenvs/dj_celery/lib/python3.6/site-packages/redis/client.py", line 760, in info
        return self.execute_command('INFO')
      File "/home/wx/pyenvs/dj_celery/lib/python3.6/site-packages/redis/client.py", line 670, in execute_command
        connection.disconnect()
      File "/home/wx/pyenvs/dj_celery/lib/python3.6/site-packages/kombu/transport/redis.py", line 866, in disconnect
        channel._on_connection_disconnect(self)
      File "/home/wx/pyenvs/dj_celery/lib/python3.6/site-packages/kombu/transport/redis.py", line 496, in _on_connection_disconnect
        self._disconnect_pools()
      File "/home/wx/pyenvs/dj_celery/lib/python3.6/site-packages/kombu/transport/redis.py", line 484, in _disconnect_pools
        self._async_pool.disconnect()
      File "/home/wx/pyenvs/dj_celery/lib/python3.6/site-packages/redis/connection.py", line 998, in disconnect
        connection.disconnect()
      File "/home/wx/pyenvs/dj_celery/lib/python3.6/site-packages/kombu/transport/redis.py", line 866, in disconnect
        channel._on_connection_disconnect(self)
      File "/home/wx/pyenvs/dj_celery/lib/python3.6/site-packages/kombu/transport/redis.py", line 498, in _on_connection_disconnect
        raise get_redis_ConnectionError()
    redis.exceptions.ConnectionError
    
    During handling of the above exception, another exception occurred:
    
    Traceback (most recent call last):
      File "/home/wx/pyenvs/dj_celery/lib/python3.6/site-packages/tornado/gen.py", line 501, in callback
        result_list.append(f.result())
      File "/usr/lib/python3.6/concurrent/futures/_base.py", line 425, in result
        return self.__get_result()
      File "/usr/lib/python3.6/concurrent/futures/_base.py", line 384, in __get_result
        raise self._exception
      File "/usr/lib/python3.6/concurrent/futures/thread.py", line 56, in run
        result = self.fn(*self.args, **self.kwargs)
      File "/home/wx/pyenvs/dj_celery/lib/python3.6/site-packages/celery/app/control.py", line 109, in conf
        return self._request('dump_conf', with_defaults=with_defaults)
      File "/home/wx/pyenvs/dj_celery/lib/python3.6/site-packages/celery/app/control.py", line 71, in _request
        timeout=self.timeout, reply=True,
      File "/home/wx/pyenvs/dj_celery/lib/python3.6/site-packages/celery/app/control.py", line 316, in broadcast
        limit, callback, channel=channel,
      File "/home/wx/pyenvs/dj_celery/lib/python3.6/site-packages/kombu/pidbox.py", line 283, in _broadcast
        chan = channel or self.connection.default_channel
      File "/home/wx/pyenvs/dj_celery/lib/python3.6/site-packages/kombu/connection.py", line 771, in default_channel
        self.connection
      File "/home/wx/pyenvs/dj_celery/lib/python3.6/site-packages/kombu/connection.py", line 756, in connection
        self._connection = self._establish_connection()
      File "/home/wx/pyenvs/dj_celery/lib/python3.6/site-packages/kombu/connection.py", line 711, in _establish_connection
        conn = self.transport.establish_connection()
      File "/home/wx/pyenvs/dj_celery/lib/python3.6/site-packages/kombu/transport/virtual/__init__.py", line 809, in establish_connection
        self._avail_channels.append(self.create_channel(self))
      File "/home/wx/pyenvs/dj_celery/lib/python3.6/site-packages/kombu/transport/virtual/__init__.py", line 791, in create_channel
        channel = self.Channel(connection)
      File "/home/wx/pyenvs/dj_celery/lib/python3.6/site-packages/kombu/transport/redis.py", line 466, in __init__
        self._disconnect_pools()
      File "/home/wx/pyenvs/dj_celery/lib/python3.6/site-packages/kombu/transport/redis.py", line 484, in _disconnect_pools
        self._async_pool.disconnect()
      File "/home/wx/pyenvs/dj_celery/lib/python3.6/site-packages/redis/connection.py", line 998, in disconnect
        connection.disconnect()
      File "/home/wx/pyenvs/dj_celery/lib/python3.6/site-packages/kombu/transport/redis.py", line 866, in disconnect
        channel._on_connection_disconnect(self)
      File "/home/wx/pyenvs/dj_celery/lib/python3.6/site-packages/kombu/transport/redis.py", line 498, in _on_connection_disconnect
        raise get_redis_ConnectionError()
    redis.exceptions.ConnectionError
[E 200415 09:44:31 events:125] Failed to capture events: '', trying again in 4 seconds.
[E 200415 09:44:33 base_events:1285] Future exception was never retrieved
    future: <Future finished exception=ConnectionError()>
    Traceback (most recent call last):
      File "/home/wx/pyenvs/dj_celery/lib/python3.6/site-packages/kombu/transport/virtual/__init__.py", line 789, in create_channel
        return self._avail_channels.pop()
    IndexError: pop from empty list
    
    During handling of the above exception, another exception occurred:
    
    Traceback (most recent call last):
      File "/home/wx/pyenvs/dj_celery/lib/python3.6/site-packages/redis/connection.py", line 484, in connect
        sock = self._connect()
      File "/home/wx/pyenvs/dj_celery/lib/python3.6/site-packages/redis/connection.py", line 541, in _connect
        raise err
      File "/home/wx/pyenvs/dj_celery/lib/python3.6/site-packages/redis/connection.py", line 529, in _connect
        sock.connect(socket_address)
    ConnectionRefusedError: [Errno 111] Connection refused
    
    During handling of the above exception, another exception occurred:
    
    Traceback (most recent call last):
      File "/home/wx/pyenvs/dj_celery/lib/python3.6/site-packages/redis/client.py", line 667, in execute_command
        connection.send_command(*args)
      File "/home/wx/pyenvs/dj_celery/lib/python3.6/site-packages/redis/connection.py", line 610, in send_command
        self.send_packed_command(self.pack_command(*args))
      File "/home/wx/pyenvs/dj_celery/lib/python3.6/site-packages/redis/connection.py", line 585, in send_packed_command
        self.connect()
      File "/home/wx/pyenvs/dj_celery/lib/python3.6/site-packages/redis/connection.py", line 489, in connect
        raise ConnectionError(self._error_message(e))
    redis.exceptions.ConnectionError: Error 111 connecting to 127.0.0.1:6379. Connection refused.
    
    During handling of the above exception, another exception occurred:
    
    Traceback (most recent call last):
      File "/home/wx/pyenvs/dj_celery/lib/python3.6/site-packages/kombu/transport/redis.py", line 464, in __init__
        self.client.info()
      File "/home/wx/pyenvs/dj_celery/lib/python3.6/site-packages/redis/client.py", line 760, in info
        return self.execute_command('INFO')
      File "/home/wx/pyenvs/dj_celery/lib/python3.6/site-packages/redis/client.py", line 670, in execute_command
        connection.disconnect()
      File "/home/wx/pyenvs/dj_celery/lib/python3.6/site-packages/kombu/transport/redis.py", line 866, in disconnect
        channel._on_connection_disconnect(self)
      File "/home/wx/pyenvs/dj_celery/lib/python3.6/site-packages/kombu/transport/redis.py", line 496, in _on_connection_disconnect
        self._disconnect_pools()
      File "/home/wx/pyenvs/dj_celery/lib/python3.6/site-packages/kombu/transport/redis.py", line 484, in _disconnect_pools
        self._async_pool.disconnect()
      File "/home/wx/pyenvs/dj_celery/lib/python3.6/site-packages/redis/connection.py", line 998, in disconnect
        connection.disconnect()
      File "/home/wx/pyenvs/dj_celery/lib/python3.6/site-packages/kombu/transport/redis.py", line 866, in disconnect
        channel._on_connection_disconnect(self)
      File "/home/wx/pyenvs/dj_celery/lib/python3.6/site-packages/kombu/transport/redis.py", line 498, in _on_connection_disconnect
        raise get_redis_ConnectionError()
    redis.exceptions.ConnectionError
    
    During handling of the above exception, another exception occurred:
    
    Traceback (most recent call last):
      File "/home/wx/pyenvs/dj_celery/lib/python3.6/site-packages/tornado/gen.py", line 501, in callback
        result_list.append(f.result())
      File "/usr/lib/python3.6/concurrent/futures/_base.py", line 425, in result
        return self.__get_result()
      File "/usr/lib/python3.6/concurrent/futures/_base.py", line 384, in __get_result
        raise self._exception
      File "/usr/lib/python3.6/concurrent/futures/thread.py", line 56, in run
        result = self.fn(*self.args, **self.kwargs)
      File "/home/wx/pyenvs/dj_celery/lib/python3.6/site-packages/celery/app/control.py", line 109, in conf
        return self._request('dump_conf', with_defaults=with_defaults)
      File "/home/wx/pyenvs/dj_celery/lib/python3.6/site-packages/celery/app/control.py", line 71, in _request
        timeout=self.timeout, reply=True,
      File "/home/wx/pyenvs/dj_celery/lib/python3.6/site-packages/celery/app/control.py", line 316, in broadcast
        limit, callback, channel=channel,
      File "/home/wx/pyenvs/dj_celery/lib/python3.6/site-packages/kombu/pidbox.py", line 283, in _broadcast
        chan = channel or self.connection.default_channel
      File "/home/wx/pyenvs/dj_celery/lib/python3.6/site-packages/kombu/connection.py", line 771, in default_channel
        self.connection
      File "/home/wx/pyenvs/dj_celery/lib/python3.6/site-packages/kombu/connection.py", line 756, in connection
        self._connection = self._establish_connection()
      File "/home/wx/pyenvs/dj_celery/lib/python3.6/site-packages/kombu/connection.py", line 711, in _establish_connection
        conn = self.transport.establish_connection()
      File "/home/wx/pyenvs/dj_celery/lib/python3.6/site-packages/kombu/transport/virtual/__init__.py", line 809, in establish_connection
        self._avail_channels.append(self.create_channel(self))
      File "/home/wx/pyenvs/dj_celery/lib/python3.6/site-packages/kombu/transport/virtual/__init__.py", line 791, in create_channel
        channel = self.Channel(connection)
      File "/home/wx/pyenvs/dj_celery/lib/python3.6/site-packages/kombu/transport/redis.py", line 466, in __init__
        self._disconnect_pools()
      File "/home/wx/pyenvs/dj_celery/lib/python3.6/site-packages/kombu/transport/redis.py", line 484, in _disconnect_pools
        self._async_pool.disconnect()
      File "/home/wx/pyenvs/dj_celery/lib/python3.6/site-packages/redis/connection.py", line 998, in disconnect
        connection.disconnect()
      File "/home/wx/pyenvs/dj_celery/lib/python3.6/site-packages/kombu/transport/redis.py", line 866, in disconnect
        channel._on_connection_disconnect(self)
      File "/home/wx/pyenvs/dj_celery/lib/python3.6/site-packages/kombu/transport/redis.py", line 498, in _on_connection_disconnect
        raise get_redis_ConnectionError()
    redis.exceptions.ConnectionError
    
    During handling of the above exception, another exception occurred:
    
    Traceback (most recent call last):
      File "/home/wx/pyenvs/dj_celery/lib/python3.6/site-packages/tornado/gen.py", line 742, in run
        yielded = self.gen.throw(*exc_info)  # type: ignore
      File "/home/wx/pyenvs/dj_celery/lib/python3.6/site-packages/flower/api/control.py", line 39, in update_workers
        results = yield futures
      File "/home/wx/pyenvs/dj_celery/lib/python3.6/site-packages/tornado/gen.py", line 735, in run
        value = future.result()
      File "/home/wx/pyenvs/dj_celery/lib/python3.6/site-packages/tornado/gen.py", line 501, in callback
        result_list.append(f.result())
      File "/usr/lib/python3.6/concurrent/futures/_base.py", line 425, in result
        return self.__get_result()
      File "/usr/lib/python3.6/concurrent/futures/_base.py", line 384, in __get_result
        raise self._exception
      File "/usr/lib/python3.6/concurrent/futures/thread.py", line 56, in run
        result = self.fn(*self.args, **self.kwargs)
      File "/home/wx/pyenvs/dj_celery/lib/python3.6/site-packages/celery/app/control.py", line 90, in stats
        return self._request('stats')
      File "/home/wx/pyenvs/dj_celery/lib/python3.6/site-packages/celery/app/control.py", line 71, in _request
        timeout=self.timeout, reply=True,
      File "/home/wx/pyenvs/dj_celery/lib/python3.6/site-packages/celery/app/control.py", line 316, in broadcast
        limit, callback, channel=channel,
      File "/home/wx/pyenvs/dj_celery/lib/python3.6/site-packages/kombu/pidbox.py", line 283, in _broadcast
        chan = channel or self.connection.default_channel
      File "/home/wx/pyenvs/dj_celery/lib/python3.6/site-packages/kombu/connection.py", line 771, in default_channel
        self.connection
      File "/home/wx/pyenvs/dj_celery/lib/python3.6/site-packages/kombu/connection.py", line 756, in connection
        self._connection = self._establish_connection()
      File "/home/wx/pyenvs/dj_celery/lib/python3.6/site-packages/kombu/connection.py", line 711, in _establish_connection
        conn = self.transport.establish_connection()
      File "/home/wx/pyenvs/dj_celery/lib/python3.6/site-packages/kombu/transport/virtual/__init__.py", line 809, in establish_connection
        self._avail_channels.append(self.create_channel(self))
      File "/home/wx/pyenvs/dj_celery/lib/python3.6/site-packages/kombu/transport/virtual/__init__.py", line 791, in create_channel
        channel = self.Channel(connection)
      File "/home/wx/pyenvs/dj_celery/lib/python3.6/site-packages/kombu/transport/redis.py", line 466, in __init__
        self._disconnect_pools()
      File "/home/wx/pyenvs/dj_celery/lib/python3.6/site-packages/kombu/transport/redis.py", line 484, in _disconnect_pools
        self._async_pool.disconnect()
      File "/home/wx/pyenvs/dj_celery/lib/python3.6/site-packages/redis/connection.py", line 998, in disconnect
        connection.disconnect()
      File "/home/wx/pyenvs/dj_celery/lib/python3.6/site-packages/kombu/transport/redis.py", line 866, in disconnect
        channel._on_connection_disconnect(self)
      File "/home/wx/pyenvs/dj_celery/lib/python3.6/site-packages/kombu/transport/redis.py", line 498, in _on_connection_disconnect
        raise get_redis_ConnectionError()
    redis.exceptions.ConnectionError
[E 200415 09:44:36 events:125] Failed to capture events: '', trying again in 8 seconds.
[E 200415 09:44:45 events:125] Failed to capture events: '', trying again in 16 seconds.
[I 200415 09:44:51 command:44] SIGTERM detected, shutting down
